<?xml version="1.0" ?>
<!-- =================================================================================== -->
<!-- |    This document was autogenerated by xacro from kinova_standalone.xacro      | -->
<!-- |    EDITING THIS FILE BY HAND IS NOT RECOMMENDED                                 | -->
<!-- =================================================================================== -->
<!-- kinova refers to jaco v2 6DOF non-spherical 3fingers -->


<robot name="allegrokinova" xmlns:body="http://playerstage.sourceforge.net/gazebo/xmlschema/#body" xmlns:controller="http://playerstage.sourceforge.net/gazebo/xmlschema/#controller" xmlns:gazebo="http://playerstage.sourceforge.net/gazebo/xmlschema/#gz" xmlns:geom="http://playerstage.sourceforge.net/gazebo/xmlschema/#geom" xmlns:interface="http://playerstage.sourceforge.net/gazebo/xmlschema/#interface" xmlns:joint="http://playerstage.sourceforge.net/gazebo/xmlschema/#joint" xmlns:model="http://playerstage.sourceforge.net/gazebo/xmlschema/#model" xmlns:physics="http://playerstage.sourceforge.net/gazebo/xmlschema/#physics" xmlns:renderable="http://playerstage.sourceforge.net/gazebo/xmlschema/#renderable" xmlns:rendering="http://playerstage.sourceforge.net/gazebo/xmlschema/#rendering" xmlns:sensor="http://playerstage.sourceforge.net/gazebo/xmlschema/#sensor" xmlns:xi="http://www.w3.org/2001/XInclude">
  <!-- links      		mesh_no
   base           		0
   shoulder       		1
   arm            		2
   forearm        		3
   wrist          		4
   arm_mico       		5
   arm_half1 (7dof)		6
   arm_half2 (7dof)		7
   wrist_spherical_1  8
   wrist_spherical_2  9

   hand 3 finger  		55
   hand_2finger   		56
   finger_proximal		57
   finger_distal      58
-->
  <!-- links      		mesh_no
   base           		0
   shoulder       		1
   arm            		2
   forearm        		3
   wrist          		4
   arm_mico       		5
   arm_half1 (7dof)		6
   arm_half2 (7dof)		7
   wrist_spherical_1  8
   wrist_spherical_2  9

   hand 3 finger  		55
   hand_bfinger   		56
   finger_proximal		57
   finger_distal      58
   <color rgba="0.792156862745098 0.819607843137255 0.933333333333333 1"/>
-->
 
  <link name="kinova_link_base">
    <visual>
      <geometry>
        <mesh filename="package://kinova_description/meshes/base.STL"/>
      </geometry>
      <material name="carbon_fiber">
        <color rgba="0.792156862745098 0.819607843137255 0.933333333333333 1"/>
      </material>
    </visual>
    <collision>
      <geometry>
        <mesh filename="package://kinova_description/meshes/base.STL"/>
      </geometry>
    </collision>
    <inertial>
      <mass value="0.46784"/>
      <origin rpy="0 0 0" xyz="0 0 0.1255"/>
      <inertia ixx="0.000951270861568" ixy="0" ixz="0" iyy="0.000951270861568" iyz="0" izz="0.00037427200000000004"/>
    </inertial>
  </link>
  
  <link name="kinova_link_a">
    <visual>
      <geometry>
        <mesh filename="package://kinova_description/meshes/shoulder.STL"/>
      </geometry>
      <material name="carbon_fiber">
        <color rgba="0.792156862745098 0.819607843137255 0.933333333333333 1"/>
      </material>
    </visual>
    <visual>
      <geometry>
        <mesh filename="package://kinova_description/meshes/ring_big.STL"/>
      </geometry>
    </visual>
    <collision>
      <geometry>
        <mesh filename="package://kinova_description/meshes/shoulder.STL"/>
      </geometry>
    </collision>
    <inertial>
      <mass value="0.7477"/>
      <origin xyz="0 -0.002 -0.0605"/>
      <inertia ixx="0.0015203172520400004" ixy="0" ixz="0" iyy="0.0015203172520400004" iyz="0" izz="0.00059816"/>
    </inertial>
  </link>
  <joint name="kinova_joint_a" type="continuous">
    <parent link="kinova_link_base"/>
    <child link="kinova_link_a"/>
    <axis xyz="0 0 1"/>
    <limit effort="40" lower="-6.283185307179586" upper="6.283185307179586" velocity="0.6283185307179586"/>
    <origin rpy="0 3.141592653589793 0" xyz="0 0 0.15675"/>
    <dynamics damping="0.0" friction="0.0"/>
  </joint>

  <link name="kinova_link_b">
    <visual>
      <geometry>
        <mesh filename="package://kinova_description/meshes/arm.STL"/>
      </geometry>
      <material name="carbon_fiber">
        <color rgba="0.792156862745098 0.819607843137255 0.933333333333333 1"/>
      </material>
    </visual>
    <visual>
      <geometry>
        <mesh filename="package://kinova_description/meshes/ring_big.STL"/>
      </geometry>
    </visual>
    <collision>
      <geometry>
        <mesh filename="package://kinova_description/meshes/arm.STL"/>
      </geometry>
    </collision>
    <inertial>
      <mass value="0.99"/>
      <origin xyz="0 -0.2065 -0.01"/>
      <inertia ixx="0.010502207990999999" ixy="0" ixz="0" iyy="0.0007920000000000001" iyz="0" izz="0.010502207990999999"/>
    </inertial>
  </link>
  <joint name="kinova_joint_b" type="revolute">
    <parent link="kinova_link_a"/>
    <child link="kinova_link_b"/>
    <axis xyz="0 0 1"/>
    <limit effort="80" lower="0.8203047484373349" upper="5.462880558742252" velocity="0.6283185307179586"/>
    <origin rpy="-1.5707963267948966 0 3.141592653589793" xyz="0 0.0016 -0.11875"/>
    <dynamics damping="0.0" friction="0.0"/>
  </joint>

  <link name="kinova_link_c">
    <visual>
      <geometry>
        <mesh filename="package://kinova_description/meshes/forearm.STL"/>
      </geometry>
      <material name="carbon_fiber">
        <color rgba="0.792156862745098 0.819607843137255 0.933333333333333 1"/>
      </material>
    </visual>
    <visual>
      <geometry>
        <mesh filename="package://kinova_description/meshes/ring_big.STL"/>
      </geometry>
    </visual>
    <collision>
      <geometry>
        <mesh filename="package://kinova_description/meshes/forearm.STL"/>
      </geometry>
    </collision>
    <inertial>
      <mass value="0.6763"/>
      <origin xyz="0 0.081 -0.0086"/>
      <inertia ixx="0.0014202243190800001" ixy="0" ixz="0" iyy="0.000304335" iyz="0" izz="0.0014202243190800001"/>
    </inertial>
  </link>
  <joint name="kinova_joint_c" type="revolute">
    <parent link="kinova_link_b"/>
    <child link="kinova_link_c"/>
    <axis xyz="0 0 1"/>
    <limit effort="40" lower="0.33161255787892263" upper="5.951572749300664" velocity="0.6283185307179586"/>
    <origin rpy="0 3.141592653589793 0" xyz="0 -0.410 0"/>
    <dynamics damping="0.0" friction="0.0"/>
  </joint>

  <link name="kinova_link_d">
    <visual>
      <geometry>
        <mesh filename="package://kinova_description/meshes/wrist.STL"/>
      </geometry>
      <material name="carbon_fiber">
        <color rgba="0.792156862745098 0.819607843137255 0.933333333333333 1"/>
      </material>
    </visual>
    <visual>
      <geometry>
        <mesh filename="package://kinova_description/meshes/ring_small.STL"/>
      </geometry>
    </visual>
    <collision>
      <geometry>
        <mesh filename="package://kinova_description/meshes/wrist.STL"/>
      </geometry>
    </collision>
    <inertial>
      <mass value="0.426367"/>
      <origin xyz="0 -0.037 -0.0642"/>
      <inertia ixx="7.734969059999999e-05" ixy="0" ixz="0" iyy="7.734969059999999e-05" iyz="0" izz="0.0001428"/>
    </inertial>
  </link>
  <joint name="kinova_joint_d" type="continuous">
    <parent link="kinova_link_c"/>
    <child link="kinova_link_d"/>
    <axis xyz="0 0 1"/>
    <limit effort="20" lower="-6.283185307179586" upper="6.283185307179586" velocity="0.8377580409572781"/>
    <origin rpy="-1.5707963267948966 0 3.141592653589793" xyz="0 0.2073 -0.0114"/>
    <dynamics damping="0.0" friction="0.0"/>
  </joint>


  <link name="kinova_link_e">
    <visual>
      <geometry>
        <mesh filename="package://kinova_description/meshes/wrist.STL"/>
      </geometry>
      <material name="carbon_fiber">
        <color rgba="0.792156862745098 0.819607843137255 0.933333333333333 1"/>
      </material>
    </visual>
    <visual>
      <geometry>
        <mesh filename="package://kinova_description/meshes/ring_small.STL"/>
      </geometry>
    </visual>
    <collision>
      <geometry>
        <mesh filename="package://kinova_description/meshes/wrist.STL"/>
      </geometry>
    </collision>
    <inertial>
      <mass value="0.426367"/>
      <origin xyz="0 -0.037 -0.0642"/>
      <inertia ixx="7.734969059999999e-05" ixy="0" ixz="0" iyy="7.734969059999999e-05" iyz="0" izz="0.0001428"/>
    </inertial>
  </link>
  <joint name="kinova_joint_e" type="continuous">
    <parent link="kinova_link_d"/>
    <child link="kinova_link_e"/>
    <axis xyz="0 0 1"/>
    <limit effort="20" lower="-6.283185307179586" upper="6.283185307179586" velocity="0.8377580409572781"/>
    <origin rpy="1.0471975511965976 0 3.141592653589793" xyz="0 -0.03703 -0.06414"/>
    <dynamics damping="0.0" friction="0.0"/>
  </joint>

  <link name="kinova_end_effector"/>
  <joint name="kinova_joint_end_effector" type="continuous">
    <parent link="kinova_link_e"/>
    <child link="kinova_end_effector"/>
    <axis xyz="0 0 1"/>
    <limit effort="20" lower="-6.283185307179586" upper="6.283185307179586" velocity="0.8377580409572781"/>
    <origin rpy="1.0471975511965976 0 3.141592653589793" xyz="0 -0.03703 -0.06414"/>
    <dynamics damping="0.0" friction="0.0"/>
  </joint>

  <!-- BASE -->
  <link name="allegro_mount">
    <inertial>
      <mass value="0.05"/>
      <origin rpy="0 0 0" xyz="0 0 0"/>
      <inertia ixx="1e-4" ixy="0" ixz="0" iyy="1e-4" iyz="0" izz="1e-4"/> 
    </inertial>
    <visual>
      <origin rpy="1.57 0 1.57" xyz="0.01 -0.02 -0.05"/>
      <geometry>
        <mesh filename="package://allegro_hand_description/meshes/mounts/Part4.STL"  scale="1 1 .9"/>
      </geometry>
      <material name="color_j7"/>
    </visual>
    <collision>
      <origin rpy="0 0 0" xyz="0 0 0"/>
      <geometry>
        <mesh filename="package://allegro_hand_description/meshes/mounts/Part4.STL"  scale="1 1 .9"/>
      </geometry>
    </collision>
  </link>
  
  <joint name="kinova_allegro_hand" type="fixed">
    <parent link="kinova_end_effector"/>
    <child link="allegro_mount"/>
    <origin rpy="0 3.14 3.14" xyz="0 0 -0.04"/>
 </joint>

  
  
  <joint name="allegro_mount_joint" type="fixed">
    <parent link="allegro_mount"/>
    <child link="palm_link"/>
    <origin rpy="0 0 1.57" xyz="0 0.02 0.1"/>
  </joint>

  <!-- Allegro urdf parameters added-->
  <link name="palm_link">
    <visual>
      <geometry>
        <mesh filename="package://allegro_hand_description/meshes/base_link.STL"/>
      </geometry>
      <origin rpy="0 0 0" xyz="0 0 0 "/>
      <material name="black">
        <color rgba="0.2 0.2 0.2 1"/>
      </material>
    </visual>
    <collision>
      <origin rpy="0 0 0" xyz="-0.009300 0 -0.0475"/>
      <geometry>
        <box size="0.0408 0.1130 0.095"/>
      </geometry>
    </collision>
    <inertial>
      <origin rpy="0 0 0" xyz="0 0 0.0475"/>
      <mass value="0.4154"/>
      <inertia ixx="1e-4" ixy="0.0" ixz="0.0" iyy="1e-4" iyz="0.0" izz="1e-4"/>
    </inertial>
  </link>
  <!-- ============================================================================= -->
  <!-- FINGERS -->
  <!-- RIGHT HAND due to which finger is number 0 -->
  <!-- for LEFT HAND switch the sign of the **offset_origin_y** and **finger_angle_r** parameters-->
  <!-- [LINK 0, 4, 8] -->
  <link name="allegro_link_a">
    <visual>
      <geometry>
        <mesh filename="package://allegro_hand_description/meshes/link_0.0.STL"/>
      </geometry>
      <material name="black"/>
    </visual>
    <collision>
      <geometry>
        <box size="0.0196 0.0275 0.0164"/>
      </geometry>
      <origin rpy="0 0 0" xyz="0 0 0.0082"/>
    </collision>
    <inertial>
      <mass value="0.0119"/>
      <origin rpy="0 0 0" xyz="0 0 0"/>
      <inertia ixx="1.01666658333e-06" ixy="0.0" ixz="0.0" iyy="6.47677333333e-07" iyz="0.0" izz="1.01666658333e-06"/>
    </inertial>
  </link>
  <joint name="allegro_joint_a" type="revolute">
    <axis xyz="0 0 1"/>
    <limit effort="15" lower="-0.47" upper="0.47" velocity="7"/>
    <parent link="palm_link"/>
    <child link="allegro_link_a"/>
    <origin rpy="-0.08726646255 0 0" xyz="0 0.0435 -0.001542"/>
    <dynamics damping="3" friction="10"/>
  </joint>
  <!-- [LINK 1, 5, 9] -->
  <link name="allegro_link_b">
    <visual>
      <geometry>
        <mesh filename="package://allegro_hand_description/meshes/link_1.0.STL"/>
      </geometry>
      <material name="black"/>
    </visual>
    <collision>
      <geometry>
        <box size="0.0196 0.0275 0.054"/>
      </geometry>
      <origin rpy="0 0 0" xyz="0 0 0.027"/>
    </collision>
    <inertial>
      <mass value="0.065"/>
      <origin rpy="0 0 0" xyz="0 0 0"/>
      <inertia ixx="7.95654166667e-05" ixy="1.7199e-05" ixz="8.75875e-06" iyy="2.47088833333e-05" iyz="2.413125e-05" izz="7.95654166667e-05"/>
    </inertial>
  </link>
  <joint name="allegro_joint_b" type="revolute">
    <limit effort="15" lower="-0.230" upper="1.61" velocity="7"/>
    <axis xyz="0 1 0"/>
    <parent link="allegro_link_a"/>
    <child link="allegro_link_b"/>
    <origin xyz="0 0 0.0164"/>
    <dynamics damping="3" friction="5"/>
  </joint>
  <!-- [LINK 2, 6, 10]-->
  <link name="allegro_link_c">
    <visual>
      <geometry>
        <mesh filename="package://allegro_hand_description/meshes/link_2.0.STL"/>
      </geometry>
      <material name="black"/>
    </visual>
    <collision>
      <geometry>
        <box size="0.0196 0.0275 0.0384"/>
      </geometry>
      <origin rpy="0 0 0" xyz="0 0 0.0192"/>
    </collision>
    <inertial>
      <mass value="0.0355"/>
      <origin rpy="0 0 0" xyz="0 0 0"/>
      <inertia ixx="2.63979183333e-05" ixy="6.67968e-06" ixz="4.783625e-06" iyy="1.34948516667e-05" iyz="9.372e-06" izz="2.63979183333e-05"/>
    </inertial>
  </link>
  <joint name="allegro_joint_c" type="revolute">
    <axis xyz="0 1 0"/>
    <limit effort="15" lower="-0.174" upper="1.709" velocity="7"/>
    <parent link="allegro_link_b"/>
    <child link="allegro_link_c"/>
    <origin xyz="0 0 0.054"/>
    <dynamics damping="8" friction="10"/>
  </joint>
  <!-- [LINK 3, 7, 11] -->
  <link name="allegro_link_d">
    <visual>
      <geometry>
        <mesh filename="package://allegro_hand_description/meshes/link_3.0.STL"/>
      </geometry>
      <material name="black"/>
    </visual>
    <collision>
      <geometry>
        <box size="0.0196 0.0275 0.0267"/>
      </geometry>
      <origin rpy="0 0 0" xyz="0 0 0.01335"/>
    </collision>
    <inertial>
      <mass value="0.0096"/>
      <origin rpy="0 0 0" xyz="0 0 0"/>
      <inertia ixx="4.701248e-06" ixy="1.255968e-06" ixz="1.2936e-06" iyy="3.649312e-06" iyz="1.7622e-06" izz="4.701248e-06"/>
    </inertial>
  </link>
  <joint name="allegro_joint_d" type="revolute">
    <axis xyz="0 1 0"/>
    <limit effort="15" lower="-0.227" upper="1.618" velocity="7"/>
    <parent link="allegro_link_c"/>
    <child link="allegro_link_d"/>
    <origin xyz="0 0 0.0384"/>
    <dynamics damping="10" friction="12"/>
  </joint>
  <!-- [FINGER TIP] -->
  <link name="allegro_link_d_tip">
    <visual>
      <geometry>
        <mesh filename="package://allegro_hand_description/meshes/link_3.0_tip.STL"/>
      </geometry>
      <material name="white">
        <color rgba=".9 .9 .9 1"/>
      </material>
    </visual>
    <collision>
      <geometry>
        <sphere radius="0.012"/>
      </geometry>
    </collision>
    <inertial>
      <mass value="0.0168"/>
      <origin rpy="0 0 0" xyz="0 0 0"/>
      <inertia ixx="9.68e-07" ixy="0" ixz="0" iyy="9.68e-07" iyz="0" izz="9.68e-07"/>
    </inertial>
  </link>
  <joint name="allegro_joint_d_tip" type="fixed">
    <parent link="allegro_link_d"/>
    <child link="allegro_link_d_tip"/>
    <origin rpy="0 0 0" xyz="0 0 0.0267"/>
  </joint>
  <!-- [LINK 0, 4, 8] -->
  <link name="allegro_link_e">
    <visual>
      <geometry>
        <mesh filename="package://allegro_hand_description/meshes/link_0.0.STL"/>
      </geometry>
      <material name="black"/>
    </visual>
    <collision>
      <geometry>
        <box size="0.0196 0.0275 0.0164"/>
      </geometry>
      <origin rpy="0 0 0" xyz="0 0 0.0082"/>
    </collision>
    <inertial>
      <mass value="0.0119"/>
      <origin rpy="0 0 0" xyz="0 0 0"/>
      <inertia ixx="1.01666658333e-06" ixy="0.0" ixz="0.0" iyy="6.47677333333e-07" iyz="0.0" izz="1.01666658333e-06"/>
    </inertial>
  </link>
  <joint name="allegro_joint_e" type="revolute">
    <axis xyz="0 0 1"/>
    <limit effort="15" lower="-0.47" upper="0.47" velocity="7"/>
    <parent link="palm_link"/>
    <child link="allegro_link_e"/>
    <origin rpy="0.0 0 0" xyz="0 0 0.0007"/>
    <dynamics damping="3" friction="10"/>
  </joint>
  <!-- [LINK 1, 5, 9] -->
  <link name="allegro_link_f">
    <visual>
      <geometry>
        <mesh filename="package://allegro_hand_description/meshes/link_1.0.STL"/>
      </geometry>
      <material name="black"/>
    </visual>
    <collision>
      <geometry>
        <box size="0.0196 0.0275 0.054"/>
      </geometry>
      <origin rpy="0 0 0" xyz="0 0 0.027"/>
    </collision>
    <inertial>
      <mass value="0.065"/>
      <origin rpy="0 0 0" xyz="0 0 0"/>
      <inertia ixx="7.95654166667e-05" ixy="1.7199e-05" ixz="8.75875e-06" iyy="2.47088833333e-05" iyz="2.413125e-05" izz="7.95654166667e-05"/>
    </inertial>
  </link>
  <joint name="allegro_joint_f" type="revolute">
    <limit effort="15" lower="-0.230" upper="1.61" velocity="7"/>
    <axis xyz="0 1 0"/>
    <parent link="allegro_link_e"/>
    <child link="allegro_link_f"/>
    <origin xyz="0 0 0.0164"/>
    <dynamics damping="3" friction="5"/>
  </joint>
  <!-- [LINK 2, 6, 10]-->
  <link name="allegro_link_g">
    <visual>
      <geometry>
        <mesh filename="package://allegro_hand_description/meshes/link_2.0.STL"/>
      </geometry>
      <material name="black"/>
    </visual>
    <collision>
      <geometry>
        <box size="0.0196 0.0275 0.0384"/>
      </geometry>
      <origin rpy="0 0 0" xyz="0 0 0.0192"/>
    </collision>
    <inertial>
      <mass value="0.0355"/>
      <origin rpy="0 0 0" xyz="0 0 0"/>
      <inertia ixx="2.63979183333e-05" ixy="6.67968e-06" ixz="4.783625e-06" iyy="1.34948516667e-05" iyz="9.372e-06" izz="2.63979183333e-05"/>
    </inertial>
  </link>
  <joint name="allegro_joint_g" type="revolute">
    <axis xyz="0 1 0"/>
    <limit effort="15" lower="-0.174" upper="1.709" velocity="7"/>
    <parent link="allegro_link_f"/>
    <child link="allegro_link_g"/>
    <origin xyz="0 0 0.054"/>
    <dynamics damping="8" friction="10"/>
  </joint>
  <!-- [LINK 3, 7, 11] -->
  <link name="allegro_link_h">
    <visual>
      <geometry>
        <mesh filename="package://allegro_hand_description/meshes/link_3.0.STL"/>
      </geometry>
      <material name="black"/>
    </visual>
    <collision>
      <geometry>
        <box size="0.0196 0.0275 0.0267"/>
      </geometry>
      <origin rpy="0 0 0" xyz="0 0 0.01335"/>
    </collision>
    <inertial>
      <mass value="0.0096"/>
      <origin rpy="0 0 0" xyz="0 0 0"/>
      <inertia ixx="4.701248e-06" ixy="1.255968e-06" ixz="1.2936e-06" iyy="3.649312e-06" iyz="1.7622e-06" izz="4.701248e-06"/>
    </inertial>
  </link>
  <joint name="allegro_joint_h" type="revolute">
    <axis xyz="0 1 0"/>
    <limit effort="15" lower="-0.227" upper="1.618" velocity="7"/>
    <parent link="allegro_link_g"/>
    <child link="allegro_link_h"/>
    <origin xyz="0 0 0.0384"/>
    <dynamics damping="10" friction="12"/>
  </joint>
  <!-- [FINGER TIP] -->
  <link name="allegro_link_h_tip">
    <visual>
      <geometry>
        <mesh filename="package://allegro_hand_description/meshes/link_3.0_tip.STL"/>
      </geometry>
      <material name="white">
        <color rgba=".9 .9 .9 1"/>
      </material>
    </visual>
    <collision>
      <geometry>
        <sphere radius="0.012"/>
      </geometry>
    </collision>
    <inertial>
      <mass value="0.0168"/>
      <origin rpy="0 0 0" xyz="0 0 0"/>
      <inertia ixx="9.68e-07" ixy="0" ixz="0" iyy="9.68e-07" iyz="0" izz="9.68e-07"/>
    </inertial>
  </link>
  <joint name="allegro_joint_h_tip" type="fixed">
    <parent link="allegro_link_h"/>
    <child link="allegro_link_h_tip"/>
    <origin rpy="0 0 0" xyz="0 0 0.0267"/>
  </joint>
  <!-- [LINK 0, 4, 8] -->
  <link name="allegro_link_j">
    <visual>
      <geometry>
        <mesh filename="package://allegro_hand_description/meshes/link_0.0.STL"/>
      </geometry>
      <material name="black"/>
    </visual>
    <collision>
      <geometry>
        <box size="0.0196 0.0275 0.0164"/>
      </geometry>
      <origin rpy="0 0 0" xyz="0 0 0.0082"/>
    </collision>
    <inertial>
      <mass value="0.0119"/>
      <origin rpy="0 0 0" xyz="0 0 0"/>
      <inertia ixx="1.01666658333e-06" ixy="0.0" ixz="0.0" iyy="6.47677333333e-07" iyz="0.0" izz="1.01666658333e-06"/>
    </inertial>
  </link>
  <joint name="allegro_joint_j" type="revolute">
    <axis xyz="0 0 1"/>
    <limit effort="15" lower="-0.47" upper="0.47" velocity="7"/>
    <parent link="palm_link"/>
    <child link="allegro_link_j"/>
    <origin rpy="0.08726646255 0 0" xyz="0 -0.0435 -0.001542"/>
    <dynamics damping="3" friction="10"/>
  </joint>
  <!-- [LINK 1, 5, 9] -->
  <link name="allegro_link_k">
    <visual>
      <geometry>
        <mesh filename="package://allegro_hand_description/meshes/link_1.0.STL"/>
      </geometry>
      <material name="black"/>
    </visual>
    <collision>
      <geometry>
        <box size="0.0196 0.0275 0.054"/>
      </geometry>
      <origin rpy="0 0 0" xyz="0 0 0.027"/>
    </collision>
    <inertial>
      <mass value="0.065"/>
      <origin rpy="0 0 0" xyz="0 0 0"/>
      <inertia ixx="7.95654166667e-05" ixy="1.7199e-05" ixz="8.75875e-06" iyy="2.47088833333e-05" iyz="2.413125e-05" izz="7.95654166667e-05"/>
    </inertial>
  </link>
  <joint name="allegro_joint_k" type="revolute">
    <limit effort="15" lower="-0.230" upper="1.61" velocity="7"/>
    <axis xyz="0 1 0"/>
    <parent link="allegro_link_j"/>
    <child link="allegro_link_k"/>
    <origin xyz="0 0 0.0164"/>
    <dynamics damping="3" friction="5"/>
  </joint>
  <!-- [LINK 2, 6, 10]-->
  <link name="allegro_link_l">
    <visual>
      <geometry>
        <mesh filename="package://allegro_hand_description/meshes/link_2.0.STL"/>
      </geometry>
      <material name="black"/>
    </visual>
    <collision>
      <geometry>
        <box size="0.0196 0.0275 0.0384"/>
      </geometry>
      <origin rpy="0 0 0" xyz="0 0 0.0192"/>
    </collision>
    <inertial>
      <mass value="0.0355"/>
      <origin rpy="0 0 0" xyz="0 0 0"/>
      <inertia ixx="2.63979183333e-05" ixy="6.67968e-06" ixz="4.783625e-06" iyy="1.34948516667e-05" iyz="9.372e-06" izz="2.63979183333e-05"/>
    </inertial>
  </link>
  <joint name="allegro_joint_l" type="revolute">
    <axis xyz="0 1 0"/>
    <limit effort="15" lower="-0.174" upper="1.709" velocity="7"/>
    <parent link="allegro_link_k"/>
    <child link="allegro_link_l"/>
    <origin xyz="0 0 0.054"/>
    <dynamics damping="8" friction="10"/>
  </joint>
  <!-- [LINK 3, 7, 11] -->
  <link name="allegro_link_m">
    <visual>
      <geometry>
        <mesh filename="package://allegro_hand_description/meshes/link_3.0.STL"/>
      </geometry>
      <material name="black"/>
    </visual>
    <collision>
      <geometry>
        <box size="0.0196 0.0275 0.0267"/>
      </geometry>
      <origin rpy="0 0 0" xyz="0 0 0.01335"/>
    </collision>
    <inertial>
      <mass value="0.0096"/>
      <origin rpy="0 0 0" xyz="0 0 0"/>
      <inertia ixx="4.701248e-06" ixy="1.255968e-06" ixz="1.2936e-06" iyy="3.649312e-06" iyz="1.7622e-06" izz="4.701248e-06"/>
    </inertial>
  </link>
  <joint name="allegro_joint_m" type="revolute">
    <axis xyz="0 1 0"/>
    <limit effort="15" lower="-0.227" upper="1.618" velocity="7"/>
    <parent link="allegro_link_l"/>
    <child link="allegro_link_m"/>
    <origin xyz="0 0 0.0384"/>
    <dynamics damping="10" friction="12"/>
  </joint>
  <!-- [FINGER TIP] -->
  <link name="allegro_link_m_tip">
    <visual>
      <geometry>
        <mesh filename="package://allegro_hand_description/meshes/link_3.0_tip.STL"/>
      </geometry>
      <material name="white">
        <color rgba=".9 .9 .9 1"/>
      </material>
    </visual>
    <collision>
      <geometry>
        <sphere radius="0.012"/>
      </geometry>
    </collision>
    <inertial>
      <mass value="0.0168"/>
      <origin rpy="0 0 0" xyz="0 0 0"/>
      <inertia ixx="9.68e-07" ixy="0" ixz="0" iyy="9.68e-07" iyz="0" izz="9.68e-07"/>
    </inertial>
  </link>
  <joint name="allegro_joint_m_tip" type="fixed">
    <parent link="allegro_link_m"/>
    <child link="allegro_link_m_tip"/>
    <origin rpy="0 0 0" xyz="0 0 0.0267"/>
  </joint>
  <!-- THUMB -->
  <!-- [LINK 12] -->
  <link name="allegro_link_n">
    <visual>
      <geometry>
        <mesh filename="package://allegro_hand_description/meshes/link_12.0_right.STL"/>
      </geometry>
      <material name="black">
        <color rgba=".2 .2 .2 1"/>
      </material>
      <origin rpy="0 0 0" xyz="0 0 0"/>
    </visual>
    <collision>
      <geometry>
        <box size="0.0358 0.034 0.0455"/>
      </geometry>
      <origin rpy="0 0 0" xyz="-0.0179 0.009 0.0145"/>
    </collision>
    <inertial>
      <mass value="0.0176"/>
      <origin rpy="0 0 0" xyz="0 0 0"/>
      <inertia ixx="1.89273333333e-5" ixy="7.16716e-06" ixz="5.35568e-06" iyy="1.43008213333e-05" iyz="6.8068e-06" izz="1.89273333333e-05"/>
    </inertial>
  </link>
  <joint name="allegro_joint_n" type="revolute">
    <axis xyz="-1 0 0"/>
    <limit effort="15" lower="0.263" upper="1.396" velocity="7"/>
    <parent link="palm_link"/>
    <child link="allegro_link_n"/>
    <origin rpy="0 -1.65806278845 -1.5707963259" xyz="-0.0182 0.019333 -0.045987"/>
    <dynamics damping="3" friction="10"/>
  </joint>
  <!-- [LINK 13] -->
  <link name="allegro_link_o">
    <visual>
      <geometry>
        <mesh filename="package://allegro_hand_description/meshes/link_13.0.STL"/>
      </geometry>
      <material name="black">
        <color rgba=".2 .2 .2 1"/>
      </material>
    </visual>
    <collision>
      <geometry>
        <box size="0.0196 0.0275 0.0177"/>
      </geometry>
      <origin rpy="0 0 0" xyz="0 0 0.00885"/>
    </collision>
    <inertial>
      <mass value="0.0119"/>
      <origin rpy="0 0 0" xyz="0 0 0"/>
      <inertia ixx="4.24250866667e-06" ixy="1.032087e-06" ixz="1.603525e-06" iyy="4.52362633333e-06" iyz="1.44808125e-06" izz="4.24250866667e-06"/>
    </inertial>
  </link>
  <joint name="allegro_joint_o" type="revolute">
    <axis xyz="0 0 1"/>
    <limit effort="15" lower="-0.105" upper="2" velocity="7"/>
    <parent link="allegro_link_n"/>
    <child link="allegro_link_o"/>
    <origin xyz="-0.027 0.005 0.0399"/>
    <dynamics damping="3" friction="5"/>
  </joint>
  <!-- [LINK 14] -->
  <link name="allegro_link_p">
    <visual>
      <geometry>
        <mesh filename="package://allegro_hand_description/meshes/link_14.0.STL"/>
      </geometry>
      <material name="black">
                </material>
    </visual>
    <collision>
      <geometry>
        <box size="0.0196 0.0275 0.0514"/>
      </geometry>
      <origin rpy="0 0 0" xyz="0 0 0.0257"/>
    </collision>
    <inertial>
      <mass value="0.038"/>
      <origin rpy="0 0 0" xyz="0 0 0"/>
      <inertia ixx="4.30439933333e-05" ixy="9.57068e-06" ixz="5.1205e-06" iyy="1.44451933333e-05" iyz="1.342825e-05" izz="4.30439933333e-05"/>
    </inertial>
  </link>
  <joint name="allegro_joint_p" type="revolute">
    <axis xyz="0 1 0"/>
    <limit effort="15" lower="-0.189" upper="1.644" velocity="7"/>
    <parent link="allegro_link_o"/>
    <child link="allegro_link_p"/>
    <origin xyz="0 0 0.0177"/>
    <dynamics damping="3" friction="10"/>
  </joint>
  <!-- [LINK 15] -->
  <link name="allegro_link_r">
    <visual>
      <geometry>
        <mesh filename="package://allegro_hand_description/meshes/link_15.0.STL"/>
      </geometry>
      <material name="black">
                </material>
    </visual>
    <collision>
      <geometry>
        <box size="0.0196 0.0275 0.0423"/>
      </geometry>
      <origin rpy="0 0 0" xyz="0 0 0.02115"/>
    </collision>
    <inertial>
      <mass value="0.0388"/>
      <origin rpy="0 0 0" xyz="0 0 0"/>
      <inertia ixx="3.29223173333e-05" ixy="8.042076e-06" ixz="5.2283e-06" iyy="1.47493026667e-5" iyz="1.1283525e-5" izz="3.29223173333e-05"/>
    </inertial>
  </link>
  <joint name="allegro_joint_r" type="revolute">
    <axis xyz="0 1 0"/>
    <limit effort="15" lower="-0.162" upper="1.719" velocity="7"/>
    <parent link="allegro_link_p"/>
    <child link="allegro_link_r"/>
    <origin xyz="0 0 0.0514"/>
    <dynamics damping="3" friction="12"/>
  </joint>
  <!-- [FINGER TIP] -->
  <link name="allegro_link_r_tip">
    <visual>
      <geometry>
        <mesh filename="package://allegro_hand_description/meshes/link_15.0_tip.STL"/>
      </geometry>
      <material name="white">
        <color rgba=".9 .9 .9 1"/>
      </material>
    </visual>
    <collision>
      <geometry>
        <sphere radius="0.012"/>
      </geometry>
      <origin rpy="0 0 0" xyz="0 0 0"/>
    </collision>
    <inertial>
      <mass value="0.0168"/>
      <origin rpy="0 0 0" xyz="0 0 0"/>
      <inertia ixx="9.68e-07" ixy="0" ixz="0" iyy="9.68e-07" iyz="0" izz="9.68e-07"/>
    </inertial>
  </link>
  <joint name="allegro_joint_r_tip" type="fixed">
    <parent link="allegro_link_r"/>
    <child link="allegro_link_r_tip"/>
    <origin rpy="0 0 0" xyz="0 0 0.0423"/>
  </joint>
  
</robot>
